<?xml version="1.0"?>
<robot name="diff_robot" xmlns:xacro="http://ros.org/wiki/xacro">
  <xacro:include filename="$(find ugv_description)/urdf/simple_diff_robot_gazebo.xacro"/>

  <link name="base_footprint"/>

  <joint name="base_joint" type="fixed">
    <parent link="base_footprint"/>
    <child link="base_link"/>
    <origin xyz="0 0 0.028" rpy="0 0 0"/>
  </joint>

  <link name="base_link"> <!-- Important: Every visual, collision and inertial tag has its own origin -->
    <visual>
      <origin xyz="-0.0001 0 0" rpy="0 0 -1.57"/>
      <geometry>
        <!--box size="0.094 0.160 0.1265"/-->
        <!--mesh filename="package://ugv_description/meshes/collada/modelo_base_diff_base_v2.dae" scale="1 1 1"/-->
        <mesh filename="package://ugv_description/meshes/wavefront/modelo_base_diff_base_v2.obj" scale="1 1 1"/>
      </geometry>
    </visual>

    <collision>
      <origin xyz="-0.0485 0 0.050" rpy="0 0 -1.57"/>
      <geometry>
        <box size="0.094 0.160 0.1265"/>
      </geometry>
    </collision>

    <inertial>
      <origin xyz="-0.0485 0 0.050" rpy="0 0 -1.57"/>
      <!-- origin xyz="-0.0001 0 0.050" rpy="0 0 -1.57"/--> <!-- Since a plugin is used, an offset along its X axis can affect the robot behavior -->
      <mass value="0.536"/>
      <inertia ixx="1.838e-03" ixy="0" ixz="0"
               iyy="1.104e-03" iyz="0"
               izz="1.524e-03" />
    </inertial>
  </link>

  <!-- Wheels definition (joints and links) -->
  <joint name="wheel_left_joint" type="continuous">
    <parent link="base_link"/>
    <child link="wheel_left_link"/>
    <origin xyz="0 0.061 0" rpy="-1.57 0 0"/>
    <axis xyz="0 0 1"/>
  </joint>

  <link name="wheel_left_link">
    <visual>
      <origin xyz="0 0 0" rpy="1.57 1.57 0"/>
      <geometry>
        <!--cylinder length="0.018" radius="0.033"/-->
        <mesh filename="package://ugv_description/meshes/collada/modelo_base_diff_wheel_left_v2.dae" scale="1 1 1"/>
      </geometry>
    </visual>

    <collision>
      <origin xyz="0 0 0" rpy="0 0 0"/>
      <geometry>
        <cylinder length="0.030" radius="0.028"/>
      </geometry>
    </collision>

    <inertial>
      <origin xyz="0 0 0" />
      <mass value="0.024" />
      <inertia ixx="6.272e-06" ixy="0" ixz="0"
               iyy="6.272e-06" iyz="0"
               izz="9.408e-06" />
    </inertial>
  </link>

  <joint name="wheel_right_joint" type="continuous">
    <parent link="base_link"/>
    <child link="wheel_right_link"/>
    <origin xyz="0 -0.061 0" rpy="-1.57 0 0"/>
    <axis xyz="0 0 1"/>
  </joint>

  <link name="wheel_right_link">
    <visual>
      <origin xyz="0 0 0" rpy="1.57 1.57 0"/>
      <geometry>
        <!--cylinder length="0.018" radius="0.033"/-->
        <mesh filename="package://ugv_description/meshes/collada/modelo_base_diff_wheel_right_v2.dae" scale="1 1 1"/>
      </geometry>
    </visual>

    <collision>
      <origin xyz="0 0 0" rpy="0 0 0"/>
      <geometry>
        <cylinder length="0.030" radius="0.028"/>
      </geometry>
    </collision>

    <inertial>
      <origin xyz="0 0 0" />
      <mass value="0.024" />
      <inertia ixx="6.272e-06" ixy="0" ixz="0"
               iyy="6.272e-06" iyz="0"
               izz="9.408e-06" />
    </inertial>
  </link>

  <!-- Caster wheel definition (joint and link) -->
  <joint name="caster_joint" type="fixed">
    <parent link="base_link"/>
    <child link="caster_link"/>
    <origin xyz="-0.106 0 -0.016" rpy="0 0 0"/>
  </joint>

  <link name="caster_link">
    <visual>
      <origin xyz="0 0 0" rpy="0 0 -1.57"/>
      <geometry>
        <mesh filename="package://ugv_description/meshes/collada/modelo_base_diff_wheel_caster_v2.dae" scale="1 1 1"/>
        <!--sphere radius="0.009"/-->
      </geometry>
    </visual>
    
    <collision>
      <origin xyz="0 0 0" rpy="0 0 0"/>
      <geometry>
        <sphere radius="0.009"/>
      </geometry>
    </collision>
    <!-- Since the caster wheel is only a point of contact, inertial tag can be ommited -->
  </link>

  <!--inertial>
      <origin xyz="0 0 0" />
      <mass value="0.024" />
      <inertia ixx="7.780e-07" ixy="0" ixz="0"
               iyy="7.780e-07" iyz="0"
               izz="7.780e-07" />
    </inertial-->

</robot>
